Workbook

Sheet Summary
B2: ASML | 3-Statement Model & DCF Valuation | T2: ="SUMMMARY VALUES - "&UPPER(CHOOSE(Scenarios!$D$7,Scenarios!C14,Scenarios!C15,Scenarios!C16)) -> SUMMMARY VALUES - BASE CASE
B3: Summary Outputs | AD3: Projected
X4: Trend | Y4: =Model!G7 -> 2020 | Z4: =Model!H7 -> 2021 | AA4: =Model!I7 -> 2022 | AB4: =Model!J7 -> 2023 | AC4: =Model!K7 -> 2024 | AD4: =Model!L7 -> 2025 | AE4: =Model!M7 -> 2026 | AF4: =Model!N7 -> 2027 | ... AH4: =Model!P7 -> 2029
B6: SUMMMARY VALUES - BASE CASE
L7: Projected | U7: Income Statement Items
C8: (€ Millions) | F8: Trend | G8: =Y4 -> 2020 | H8: =Z4 -> 2021 | I8: =AA4 -> 2022 | J8: =AB4 -> 2023 | K8: =AC4 -> 2024 | L8: =AD4 -> 2025 | M8: =AE4 -> 2026 | N8: =AF4 -> 2027 | ... P8: =AH4 -> 2029
V9: Net Revenue | Y9: =Model!G261 -> 13978.5 | Z9: =Model!H261 -> 18611 | AA9: =Model!I261 -> 21173.4 | AB9: =Model!J261 -> 27558.5 | AC9: =Model!K261 -> 28262.9 | AD9: =Model!L261 -> 31660.435 | AE9: =Model!M261 -> 36796.818 | AF9: =Model!N261 -> 42290.181 | ... AH9: =Model!P261 -> 50624.161
V10: Growth | Z10: =Z9/Y9-1 -> 0.3314018 | AA10: =AA9/Z9-1 -> 0.13768202 | AB10: =AB9/AA9-1 -> 0.30156234 | AC10: =AC9/AB9-1 -> 0.025560172 | AD10: =AD9/AC9-1 -> 0.12021184 | AE10: =AE9/AD9-1 -> 0.1622335 | AF10: =AF9/AE9-1 -> 0.14928907 | AG10: =AG9/AF9-1 -> 0.10203979 | AH10: =AH9/AG9-1 -> 0.086228051
C11: Income Statement Items
D13: Net Revenue | G13: 13978.5 | H13: 18611 | I13: 21173.4 | J13: 27558.5 | K13: 28262.9 | L13: 31660.435 | M13: 36796.818 | N13: 42290.181 | O13: 46605.463 | P13: 50624.161 | V13: EBITDA | Y13: =Model!G286 -> 5162.2 | Z13: =Model!H286 -> 7906.5 | AA13: =Model!I286 -> 8196.9 | AB13: =Model!J286 -> 10559.4 | AC13: =Model!K286 -> 11137.2 | AD13: =Model!L286 -> 12834.601 | AE13: =Model!M286 -> 14801.367 | AF13: =Model!N286 -> 17095.418 | ... AH13: =Model!P286 -> 21109.198
D14: Growth | H14: 0.3314018 | I14: 0.13768202 | J14: 0.30156234 | K14: 0.025560172 | L14: 0.12021184 | M14: 0.1622335 | N14: 0.14928907 | O14: 0.10203979 | P14: 0.086228051 | V14: Margin | Y14: =Y13/Y9 -> 0.3692957 | Z14: =Z13/Z9 -> 0.4248294 | AA14: =AA13/AA9 -> 0.38713197 | AB14: =AB13/AB9 -> 0.38316309 | AC14: =AC13/AC9 -> 0.39405723 | AD14: =AD13/AD9 -> 0.40538297 | AE14: =AE13/AE9 -> 0.40224583 | AF14: =AF13/AF9 -> 0.40424082 | ... AH14: =AH13/AH9 -> 0.41697873
V15: Growth | Z15: =Z13/Y13-1 -> 0.53161443 | AA15: =AA13/Z13-1 -> 0.036729273 | AB15: =AB13/AA13-1 -> 0.28821872 | AC15: =AC13/AB13-1 -> 0.054719018 | AD15: =AD13/AC13-1 -> 0.15240826 | AE15: =AE13/AD13-1 -> 0.15323932 | AF15: =AF13/AE13-1 -> 0.15498911 | AG15: =AG13/AF13-1 -> 0.12443755 | AH15: =AH13/AG13-1 -> 0.098137407
D17: EBITDA | G17: 5162.2 | H17: 7906.5 | I17: 8196.9 | J17: 10559.4 | K17: 11137.2 | L17: 12834.601 | M17: 14801.367 | N17: 17095.418 | O17: 19222.729 | P17: 21109.198
D18: Margin | G18: 0.3692957 | H18: 0.4248294 | I18: 0.38713197 | J18: 0.38316309 | K18: 0.39405723 | L18: 0.40538297 | M18: 0.40224583 | N18: 0.40424082 | O18: 0.41245657 | P18: 0.41697873 | V18: Net Income | Y18: =Model!G282 -> 3696.8 | Z18: =Model!H282 -> 6134.6 | AA18: =Model!I282 -> 6395.8 | AB18: =Model!J282 -> 8115.2 | AC18: =Model!K282 -> 8349 | AD18: =Model!L282 -> 9548.6678 | AE18: =Model!M282 -> 11077.716 | AF18: =Model!N282 -> 12766.358 | ... AH18: =Model!P282 -> 15393.337
D19: Growth | H19: 0.53161443 | I19: 0.036729273 | J19: 0.28821872 | K19: 0.054719018 | L19: 0.15240826 | M19: 0.15323932 | N19: 0.15498911 | O19: 0.12443755 | P19: 0.098137407 | V19: Margin | Y19: =Y18/Y9 -> 0.26446328 | Z19: =Z18/Z9 -> 0.32962227 | AA19: =AA18/AA9 -> 0.30206769 | AB19: =AB18/AB9 -> 0.29447176 | AC19: =AC18/AC9 -> 0.29540493 | AD19: =AD18/AD9 -> 0.30159623 | AE19: =AE18/AE9 -> 0.30105091 | AF19: =AF18/AF9 -> 0.30187522 | ... AH19: =AH18/AH9 -> 0.30407096
V20: Growth | Z20: =Z18/Y18-1 -> 0.65943519 | AA20: =AA18/Z18-1 -> 0.042578163 | AB20: =AB18/AA18-1 -> 0.26883267 | AC20: =AC18/AB18-1 -> 0.028810134 | AD20: =AD18/AC18-1 -> 0.14369 | AE20: =AE18/AD18-1 -> 0.16013207 | AF20: =AF18/AE18-1 -> 0.15243592 | AG20: =AG18/AF18-1 -> 0.10560072 | AH20: =AH18/AG18-1 -> 0.090604949
D22: Net Income | G22: 3696.8 | H22: 6134.6 | I22: 6395.8 | J22: 8115.2 | K22: 8349 | L22: 9548.6678 | M22: 11077.716 | N22: 12766.358 | O22: 14114.494 | P22: 15393.337 | U22: Cash Flow Items
D23: Margin | G23: 0.26446328 | H23: 0.32962227 | I23: 0.30206769 | J23: 0.29447176 | K23: 0.29540493 | L23: 0.30159623 | M23: 0.30105091 | N23: 0.30187522 | O23: 0.30285064 | P23: 0.30407096
D24: Growth | H24: 0.65943519 | I24: 0.042578163 | J24: 0.26883267 | K24: 0.028810134 | L24: 0.14369 | M24: 0.16013207 | N24: 0.15243592 | O24: 0.10560072 | P24: 0.090604949 | V24: Operating Cash Flow | Y24: =Model!G312 -> 5306.6 | Z24: =Model!H312 -> 11592.6 | AA24: =Model!I312 -> 9434.9 | AB24: =Model!J312 -> 6536.2 | AC24: =Model!K312 -> 12369.7 | AD24: =Model!L312 -> 12312.402 | AE24: =Model!M312 -> 14696.727 | AF24: =Model!N312 -> 16398.538 | ... AH24: =Model!P312 -> 19870.422
V25: Capital Expenditures | Y25: =Model!G314 -> -962 | Z25: =Model!H314 -> -900.7 | AA25: =Model!I314 -> -1281.8 | AB25: =Model!J314 -> -2155.6 | AC25: =Model!K314 -> -2067.2 | AD25: =Model!L314 -> -1899.6261 | AE25: =Model!M314 -> -2207.8091 | AF25: =Model!N314 -> -2537.4109 | ... AH25: =Model!P314 -> -3037.4496
C26: Cash Flow Items | V26: Capitalized Dev. Costs | Y26: =Model!G315 -> -658.9 | Z26: =Model!H315 -> -725 | AA26: =Model!I315 -> -930.6 | AB26: =Model!J315 -> -985.9 | AC26: =Model!K315 -> -1138.4 | AD26: =Model!L315 -> -1266.4174 | AE26: =Model!M315 -> -1471.8727 | AF26: =Model!N315 -> -1691.6072 | ... AH26: =Model!P315 -> -2024.9664
V27: Free Cash Flow to Firm | Y27: 0 | Z27: 0 | AA27: 0 | AB27: 0 | AC27: 0 | AD27: =Valuation!L47 -> 5885.9131 | AE27: =Valuation!M47 -> 8476.1896 | AF27: =Valuation!N47 -> 10163.951 | AG27: =Valuation!O47 -> 11350.104 | AH27: =Valuation!P47 -> 12904.078
D28: Operating Cash Flow | G28: 5306.6 | H28: 11592.6 | I28: 9434.9 | J28: 6536.2 | K28: 12369.7 | L28: 12312.402 | M28: 14696.727 | N28: 16398.538 | O28: 18644.87 | P28: 19870.422
D29: Capital Expenditures | G29: -962 | H29: -900.7 | I29: -1281.8 | J29: -2155.6 | K29: -2067.2 | L29: -1899.6261 | M29: -2207.8091 | N29: -2537.4109 | O29: -2796.3278 | P29: -3037.4496 | U29: Balance Sheet Items
D30: Capitalized Dev. Costs | G30: -658.9 | H30: -725 | I30: -930.6 | J30: -985.9 | K30: -1138.4 | L30: -1266.4174 | M30: -1471.8727 | N30: -1691.6072 | O30: -1864.2185 | P30: -2024.9664
D31: Free Cash Flow to Firm | G31: 0 | H31: 0 | I31: 0 | J31: 0 | K31: 0 | L31: 5885.9131 | M31: 8476.1896 | N31: 10163.951 | O31: 11350.104 | P31: 12904.078 | V31: Total Assets | Y31: =Model!G364 -> 28866.7 | Z31: =Model!H364 -> 32131.1 | AA31: =Model!I364 -> 38826 | AB31: =Model!J364 -> 43078.6 | AC31: =Model!K364 -> 52566.5 | AD31: =Model!L364 -> 59063.594 | AE31: =Model!M364 -> 68238.526 | AF31: =Model!N364 -> 77823.43 | ... AH31: =Model!P364 -> 97056.419
V32: Net Debt | Y32: =(Model!G366+Model!G373)-Model!G342 -> -1386.6 | Z32: =(Model!H366+Model!H373)-Model!H342 -> -2876.8 | AA32: =(Model!I366+Model!I373)-Model!I342 -> -3754.1 | AB32: =(Model!J366+Model!J373)-Model!J342 -> -2373.2 | AC32: =(Model!K366+Model!K373)-Model!K342 -> -9058.6 | AD32: =(Model!L366+Model!L373)-Model!L342 -> -10590.871 | AE32: =(Model!M366+Model!M373)-Model!M342 -> -15515.172 | AF32: =(Model!N366+Model!N373)-Model!N342 -> -20663.196 | ... AH32: =(Model!P366+Model!P373)-Model!P342 -> -33226.218
C33: Balance Sheet Items | V33: Shareholders' Equity | Y33: =Model!G385 -> 15300.9 | Z33: =Model!H385 -> 11843.8 | AA33: =Model!I385 -> 11286 | AB33: =Model!J385 -> 16209.5 | AC33: =Model!K385 -> 22021.9 | AD33: =Model!L385 -> 26477.103 | AE33: =Model!M385 -> 31646.059 | AF33: =Model!N385 -> 37602.371 | ... AH33: =Model!P385 -> 51367.043
D35: Total Assets | G35: 28866.7 | H35: 32131.1 | I35: 38826 | J35: 43078.6 | K35: 52566.5 | L35: 59063.594 | M35: 68238.526 | N35: 77823.43 | O35: 87537.448 | P35: 97056.419 | U35: Valuation
D36: Net Debt | G36: -1386.6 | H36: -2876.8 | I36: -3754.1 | J36: -2373.2 | K36: -9058.6 | L36: -10590.871 | M36: -15515.172 | N36: -20663.196 | O36: -26884.547 | P36: -33226.218
D37: Shareholders' Equity | G37: 15300.9 | H37: 11843.8 | I37: 11286 | J37: 16209.5 | K37: 22021.9 | L37: 26477.103 | M37: 31646.059 | N37: 37602.371 | O37: 44186.92 | P37: 51367.043 | V37: Implied Price - GGM | Y37: 0 | Z37: 0 | AA37: 0 | AB37: 0 | AC37: 0 | AD37: =Valuation!G102 -> 392.48443
V38: Implied Price - Exit EV/EBITDA | Y38: 0 | Z38: 0 | AA38: 0 | AB38: 0 | AC38: 0 | AD38: =Valuation!H102 -> 1150.1827
C39: Valuation | V39: Current Share Price | Y39: 0 | Z39: 0 | AA39: 0 | AB39: 0 | AC39: 0 | AD39: =Assumptions!Q29 -> 1179.6
V40: Upside / (Downside) - GGM | Y40: 0 | Z40: 0 | AA40: 0 | AB40: 0 | AC40: 0 | AD40: =Valuation!G104 -> -0.66727328
D41: Implied Price - GGM | G41: 0 | H41: 0 | I41: 0 | J41: 0 | K41: 0 | L41: 392.48443 | V41: Upside / (Downside) - Exit Mult. | Y41: 0 | Z41: 0 | AA41: 0 | AB41: 0 | AC41: 0 | AD41: =Valuation!H104 -> -0.024938331
D42: Implied Price - Exit EV/EBITDA | G42: 0 | H42: 0 | I42: 0 | J42: 0 | K42: 0 | L42: 1150.1827
D43: Current Share Price | G43: 0 | H43: 0 | I43: 0 | J43: 0 | K43: 0 | L43: 1179.6
D44: Upside / (Downside) - GGM | G44: 0 | H44: 0 | I44: 0 | J44: 0 | K44: 0 | L44: -0.66727328
D45: Upside / (Downside) - Exit Mult. | G45: 0 | H45: 0 | I45: 0 | J45: 0 | K45: 0 | L45: -0.024938331
B49: SUMMMARY VALUES - BULL CASE
...

Sheet Assumptions
C2: ASML
C3: Assumptions
B10: GENERAL | K10: INTEREST RATES
B11: - | C11: First year of forecast in financial model: | H11: 2025 | K11: - | L11: Interest earned on Cash balances: | Q11: 0.02
B12: - | C12: Three scenarios have been used for EUV Units, EUV ASP, | K12: - | L12: Interest rate on Bank Revolver: | Q12: 0.04
C13: High-NA Units, High-NA ASP, DUV Units, DUV ASP, | K13: - | L13: Interest rate on Long-Term Debt: | Q13: 0.035
C14: Service Growth and Growth Margin
C16: Scenario: | F16: Impact | K16: TAXES
C17: Base Case | F17: Management Guidance
C18: Bull Case | F18: AI Demand Stronger | K18: - | L18: Tax rate assumed in the model: | Q18: 0.16
C19: Bear Case | F19: Semiconductor cycle down
B22: DEPRECIATION | K22: VALUATION
B23: - | C23: Depreciation Methodology Used: | H23: Straight Line | K23: - | L23: Risk-free Rate | Q23: 0.0299
B24: - | C24: Years remaining for depreciation of existing assets: | H24: 6 | K24: - | L24: Beta | Q24: 1.46
B25: - | C25: Years used for depreciation of new assets: | H25: 10 | K25: - | L25: Equity Risk Premium | Q25: 0.055
K26: - | L26: Terminal Growth Rate | Q26: 0.03
K27: - | L27: Exit EV/EBITDA Multiple | Q27: 30
B28: EQUITY | K28: - | L28: Shares outstanding | Q28: 385.4
B29: - | C29: Dividend Payout Ratio | H29: 0.3 | K29: - | L29: Current Share Price | Q29: 1179.6
B30: - | C30: Annual Share Buyback Ratio | H30: 0.25
B33: OTHER ASSUMPTIONS | M33: =H11 -> 2025 | N33: =M33+1 -> 2026 | O33: =N33+1 -> 2027 | P33: =O33+1 -> 2028 | Q33: =P33+1 -> 2029
B35: Working Capital Days
C36: Accounts Receivable | G36: days | M36: 60 | N36: 60 | O36: 59 | P36: 59 | Q36: 58
C37: Inventories | G37: days | M37: 280 | N37: 275 | O37: 270 | P37: 265 | Q37: 260
C38: Contract Assets | G38: days | M38: 4 | N38: 4 | O38: 4 | P38: 4 | Q38: 4
C39: Other operating current assets | G39: days | M39: 18 | N39: 18 | O39: 18 | P39: 18 | Q39: 18
C40: Accounts Payable | G40: days | M40: 90 | N40: 90 | O40: 92 | P40: 92 | Q40: 95
C41: Accrued and other liabilities | G41: days | M41: 65 | N41: 65 | O41: 65 | P41: 65 | Q41: 65
C42: Contract liabilities | G42: days | M42: 170 | N42: 170 | O42: 165 | P42: 165 | Q42: 160
B44: Change in Debt & Equity
C45: Long-Term Debt Issuance / (Repayment) | G45: MM | M45: -500 | N45: -500 | O45: -500 | P45: -500 | Q45: -500
C46: Common Stock Issuance / (Buy-back) | G46: MM | M46: -3500 | N46: -4000 | O46: -4500 | P46: -5000 | Q46: -5000
B48: Metrology Revenue Growth | G48: % | M48: 0.14 | N48: 0.12 | O48: 0.11 | P48: 0.09 | Q48: 0.09
B50: Service Revenue | G50: % of Systems Revenue | M50: 0.305 | N50: 0.31 | O50: 0.315 | P50: 0.32 | Q50: 0.325
B52: Cost of Systems Revenue | G52: % of Systems Revenue | M52: 0.49 | N52: 0.49 | O52: 0.49 | P52: 0.49 | Q52: 0.49
B54: Cost Service Revenue | G54: % of Service Revenue | M54: 0.55 | N54: 0.55 | O54: 0.55 | P54: 0.55 | Q54: 0.55
B56: Capital Expenditures | G56: % of Revenue | M56: 0.06 | N56: 0.06 | O56: 0.06 | P56: 0.06 | Q56: 0.06
B58: Timing difference | G58: % of EBT | M58: 0.02 | N58: 0.02 | O58: 0.02 | P58: 0.02 | Q58: 0.02
B60: Profit from Investment in Associates Growth | G60: % | M60: 0.025 | N60: 0.025 | O60: 0.025 | P60: 0.025 | Q60: 0.025
B62: Share Based Compensation | G62: % of Revenue | M62: 0.005 | N62: 0.005 | O62: 0.005 | P62: 0.005 | Q62: 0.005
...

Sheet Scenarios
B2: =Assumptions!C2 -> ASML
B3: Variable Drivers
B7: SCENARIO SWITCH: | D7: 1 | G7: =Assumptions!H11 -> 2025 | H7: =G7+1 -> 2026 | I7: =H7+1 -> 2027 | J7: =I7+1 -> 2028 | K7: =J7+1 -> 2029
B12: EUV Units | G12: =CHOOSE($D$7,G14,G15,G16) -> 55 | H12: =CHOOSE($D$7,H14,H15,H16) -> 65 | I12: =CHOOSE($D$7,I14,I15,I16) -> 75 | J12: =CHOOSE($D$7,J14,J15,J16) -> 80 | K12: =CHOOSE($D$7,K14,K15,K16) -> 85
C14: =Assumptions!C17 -> Base Case | G14: 55 | H14: 65 | I14: 75 | J14: 80 | K14: 85
C15: =Assumptions!C18 -> Bull Case | G15: 60 | H15: 75 | I15: 90 | J15: 100 | K15: 110
C16: =Assumptions!C19 -> Bear Case | G16: 50 | H16: 55 | I16: 60 | J16: 65 | K16: 70
B21: EUV ASP - € Millions | G21: =CHOOSE($D$7,G23,G24,G25) -> 195 | H21: =CHOOSE($D$7,H23,H24,H25) -> 205 | I21: =CHOOSE($D$7,I23,I24,I25) -> 215 | J21: =CHOOSE($D$7,J23,J24,J25) -> 230 | K21: =CHOOSE($D$7,K23,K24,K25) -> 240
C23: =C14 -> Base Case | G23: 195 | H23: 205 | I23: 215 | J23: 230 | K23: 240
C24: =C15 -> Bull Case | G24: 205 | H24: 220 | I24: 235 | J24: 250 | K24: 265
C25: =C16 -> Bear Case | G25: 180 | H25: 190 | I25: 195 | J25: 205 | K25: 215
B30: High-NA Units | G30: =CHOOSE($D$7,G32,G33,G34) -> 3 | H30: =CHOOSE($D$7,H32,H33,H34) -> 6 | I30: =CHOOSE($D$7,I32,I33,I34) -> 10 | J30: =CHOOSE($D$7,J32,J33,J34) -> 14 | K30: =CHOOSE($D$7,K32,K33,K34) -> 18
C32: =C23 -> Base Case | G32: 3 | H32: 6 | I32: 10 | J32: 14 | K32: 18
C33: =C24 -> Bull Case | G33: 4 | H33: 8 | I33: 15 | J33: 20 | K33: 25
C34: =C25 -> Bear Case | G34: 2 | H34: 4 | I34: 6 | J34: 8 | K34: 10
B39: High-NA ASP - € Millions | G39: =CHOOSE($D$7,G41,G42,G43) -> 330 | H39: =CHOOSE($D$7,H41,H42,H43) -> 340 | I39: =CHOOSE($D$7,I41,I42,I43) -> 350 | J39: =CHOOSE($D$7,J41,J42,J43) -> 360 | K39: =CHOOSE($D$7,K41,K42,K43) -> 370
C41: =C32 -> Base Case | G41: 330 | H41: 340 | I41: 350 | J41: 360 | K41: 370
C42: =C33 -> Bull Case | G42: 350 | H42: 370 | I42: 380 | J42: 400 | K42: 420
C43: =C34 -> Bear Case | G43: 320 | H43: 330 | I43: 340 | J43: 350 | K43: 360
B48: DUV Units | G48: =CHOOSE($D$7,G50,G51,G52) -> 320 | H48: =CHOOSE($D$7,H50,H51,H52) -> 340 | I48: =CHOOSE($D$7,I50,I51,I52) -> 360 | J48: =CHOOSE($D$7,J50,J51,J52) -> 370 | K48: =CHOOSE($D$7,K50,K51,K52) -> 380
C50: =C41 -> Base Case | G50: 320 | H50: 340 | I50: 360 | J50: 370 | K50: 380
C51: =C42 -> Bull Case | G51: 340 | H51: 370 | I51: 400 | J51: 420 | K51: 440
C52: =C43 -> Bear Case | G52: 300 | H52: 310 | I52: 320 | J52: 330 | K52: 340
B57: DUV ASP - € Millions | G57: =CHOOSE($D$7,G59,G60,G61) -> 40 | H57: =CHOOSE($D$7,H59,H60,H61) -> 41 | I57: =CHOOSE($D$7,I59,I60,I61) -> 42 | J57: =CHOOSE($D$7,J59,J60,J61) -> 43 | K57: =CHOOSE($D$7,K59,K60,K61) -> 44
C59: =C50 -> Base Case | G59: 40 | H59: 41 | I59: 42 | J59: 43 | K59: 44
C60: =C51 -> Bull Case | G60: 42 | H60: 44 | I60: 45 | J60: 46 | K60: 47
C61: =C52 -> Bear Case | G61: 38 | H61: 39 | I61: 40 | J61: 41 | K61: 42
B66: Service growth | G66: =CHOOSE($D$7,G68,G69,G70) -> 0.12 | H66: =CHOOSE($D$7,H68,H69,H70) -> 0.11 | I66: =CHOOSE($D$7,I68,I69,I70) -> 0.1 | J66: =CHOOSE($D$7,J68,J69,J70) -> 0.09 | K66: =CHOOSE($D$7,K68,K69,K70) -> 0.08
C68: =C59 -> Base Case | G68: 0.12 | H68: 0.11 | I68: 0.1 | J68: 0.09 | K68: 0.08
C69: =C60 -> Bull Case | G69: 0.15 | H69: 0.14 | I69: 0.13 | J69: 0.12 | K69: 0.11
C70: =C61 -> Bear Case | G70: 0.08 | H70: 0.07 | I70: 0.06 | J70: 0.06 | K70: 0.05
B75: Gross Margin | G75: =CHOOSE($D$7,G77,G78,G79) -> 0.52 | H75: =CHOOSE($D$7,H77,H78,H79) -> 0.53 | I75: =CHOOSE($D$7,I77,I78,I79) -> 0.54 | J75: =CHOOSE($D$7,J77,J78,J79) -> 0.55 | K75: =CHOOSE($D$7,K77,K78,K79) -> 0.56
C77: =C68 -> Base Case | G77: 0.52 | H77: 0.53 | I77: 0.54 | J77: 0.55 | K77: 0.56
C78: =C69 -> Bull Case | G78: 0.54 | H78: 0.56 | I78: 0.58 | J78: 0.59 | K78: 0.6
C79: =C70 -> Bear Case | G79: 0.5 | H79: 0.5 | I79: 0.51 | J79: 0.51 | K79: 0.52
B84: R&D % of Revenue | G84: =CHOOSE($D$7,G86,G87,G88) -> 0.108 | H84: =CHOOSE($D$7,H86,H87,H88) -> 0.108 | I84: =CHOOSE($D$7,I86,I87,I88) -> 0.108 | J84: =CHOOSE($D$7,J86,J87,J88) -> 0.108 | K84: =CHOOSE($D$7,K86,K87,K88) -> 0.108
C86: =C77 -> Base Case | G86: 0.108 | H86: 0.108 | I86: 0.108 | J86: 0.108 | K86: 0.108
C87: =C78 -> Bull Case | G87: 0.103 | H87: 0.103 | I87: 0.103 | J87: 0.103 | K87: 0.103
C88: =C79 -> Bear Case | G88: 0.113 | H88: 0.113 | I88: 0.113 | J88: 0.113 | K88: 0.113
B93: SG&A % of Revenue | G93: =CHOOSE($D$7,G95,G96,G97) -> 0.041 | H93: =CHOOSE($D$7,H95,H96,H97) -> 0.041 | I93: =CHOOSE($D$7,I95,I96,I97) -> 0.041 | J93: =CHOOSE($D$7,J95,J96,J97) -> 0.041 | K93: =CHOOSE($D$7,K95,K96,K97) -> 0.041
...

Sheet Model
P1: =UPPER("Currently running: "&CHOOSE(Scenarios!D7,Scenarios!C14,Scenarios!C15,Scenarios!C16)&" Scenario") -> CURRENTLY RUNNING: BASE CASE SCENARIO
B2: =Assumptions!$C$2 -> ASML
B3: Revenue Schedule
B5: (€ Millions)
L6: Projected
G7: =H7-1 -> 2020 | H7: =I7-1 -> 2021 | I7: =J7-1 -> 2022 | J7: =K7-1 -> 2023 | K7: =L7-1 -> 2024 | L7: =Assumptions!H11 -> 2025 | M7: =L7+1 -> 2026 | N7: =M7+1 -> 2027 | O7: =N7+1 -> 2028 | P7: =O7+1 -> 2029
B9: SYSTEMS
B11: Sales Volume
C12: High-NA Units (EXE) | G12: 0 | H12: 0 | I12: 0 | J12: 0 | K12: 2 | L12: =Scenarios!G30 -> 3 | M12: =Scenarios!H30 -> 6 | N12: =Scenarios!I30 -> 10 | O12: =Scenarios!J30 -> 14 | P12: =Scenarios!K30 -> 18
C13: NXE Units | G13: 31 | H13: 42 | I13: 40 | J13: 53 | K13: 42 | L13: =Scenarios!G12-L12 -> 52 | M13: =Scenarios!H12-M12 -> 59 | N13: =Scenarios!I12-N12 -> 65 | O13: =Scenarios!J12-O12 -> 66 | P13: =Scenarios!K12-P12 -> 67
C15: ArF Immersion Units | G15: 68 | H15: 81 | I15: 81 | J15: 125 | K15: 129
C16: ArF Dry Units | G16: 22 | H16: 22 | I16: 28 | J16: 32 | K16: 28
C17: KrF Units | G17: 103 | H17: 131 | I17: 151 | J17: 184 | K17: 152
C18: I-line Units | G18: 34 | H18: 33 | I18: 45 | J18: 55 | K18: 65
C19: Total DUV Units | G19: =SUM(G15:G18) -> 227 | H19: =SUM(H15:H18) -> 267 | I19: =SUM(I15:I18) -> 305 | J19: =SUM(J15:J18) -> 396 | K19: =SUM(K15:K18) -> 374 | L19: =Scenarios!G48 -> 320 | M19: =Scenarios!H48 -> 340 | N19: =Scenarios!I48 -> 360 | O19: =Scenarios!J48 -> 370 | P19: =Scenarios!K48 -> 380
B23: Pricing
C24: High-NA ASP (EXE) | G24: 0 | H24: 0 | I24: 0 | J24: 0 | K24: =K37/K12 -> 232.5 | L24: =Scenarios!G39 -> 330 | M24: =Scenarios!H39 -> 340 | N24: =Scenarios!I39 -> 350 | O24: =Scenarios!J39 -> 360 | P24: =Scenarios!K39 -> 370
C25: NXE ASP | G25: =G38/G13 -> 143.99355 | H25: =H38/H13 -> 149.61905 | I25: =I38/I13 -> 176.1325 | J25: =J38/J13 -> 172.15094 | K25: =K38/K13 -> 187.05714 | L25: =(Scenarios!G21*Scenarios!G12-Scenarios!G39*Scenarios!G30)/Model!L13 -> 187.21154 | M25: =(Scenarios!H21*Scenarios!H12-Scenarios!H39*Scenarios!H30)/Model!M13 -> 191.27119 | N25: =(Scenarios!I21*Scenarios!I12-Scenarios!I39*Scenarios!I30)/Model!N13 -> 194.23077 | O25: =(Scenarios!J21*Scenarios!J12-Scenarios!J39*Scenarios!J30)/Model!O13 -> 202.42424 | P25: =(Scenarios!K21*Scenarios!K12-Scenarios!K39*Scenarios!K30)/Model!P13 -> 205.07463
C27: ArF Immersion ASP | G27: =G40/G15 -> 57.602941 | H27: =H40/H15 -> 61.22963 | I27: =I40/I15 -> 64.648148 | J27: =J40/J15 -> 72.1392 | K27: =K40/K15 -> 74.937984
C28: ArF Dry ASP | G28: =G41/G16 -> 19.409091 | H28: =H41/H16 -> 19.631818 | I28: =I41/I16 -> 22.275 | J28: =J41/J16 -> 24.38125 | K28: =K41/K16 -> 27.657143
C29: KrF ASP | G29: =G42/G17 -> 9.8281553 | H29: =H42/H17 -> 10.08626 | I29: =I42/I17 -> 10.951656 | J29: =J42/J17 -> 11.970109 | K29: =K42/K17 -> 13.1
C30: I-line ASP | G30: =G43/G18 -> 4.3058824 | H30: =H43/H18 -> 4.3121212 | I30: =I43/I18 -> 4.7 | J30: =J43/J18 -> 5.0618182 | K30: =K43/K18 -> 5.68
C31: Total DUV ASP | G31: =G44/G19 -> 24.240969 | H31: =H44/H19 -> 25.674532 | I31: =I44/I19 -> 25.32918 | J31: =J44/J19 -> 31.006313 | K31: =K44/K19 -> 34.229412 | L31: =Scenarios!G57 -> 40 | M31: =Scenarios!H57 -> 41 | N31: =Scenarios!I57 -> 42 | O31: =Scenarios!J57 -> 43 | P31: =Scenarios!K57 -> 44
B36: Revenue
C37: High-NA Revenue (EXE) | G37: 0 | H37: 0 | I37: 0 | J37: 0 | K37: 465 | L37: =L12*L24 -> 990 | M37: =M12*M24 -> 2040 | N37: =N12*N24 -> 3500 | O37: =O12*O24 -> 5040 | P37: =P12*P24 -> 6660
C38: NXE Revenue | G38: 4463.8 | H38: 6284 | I38: 7045.3 | J38: 9124 | K38: 7856.4 | L38: =L13*L25 -> 9735 | M38: =M13*M25 -> 11285 | N38: =N13*N25 -> 12625 | O38: =O13*O25 -> 13360 | P38: =P13*P25 -> 13740
C40: ArF Immersion Revenue | G40: 3917 | H40: 4959.6 | I40: 5236.5 | J40: 9017.4 | K40: 9667
C41: ArF Dry Revenue | G41: 427 | H41: 431.9 | I41: 623.7 | J41: 780.2 | K41: 774.4
C42: KrF Revenue | G42: 1012.3 | H42: 1321.3 | I42: 1653.7 | J42: 2202.5 | K42: 1991.2
C43: I-line Revenue | G43: 146.4 | H43: 142.3 | I43: 211.5 | J43: 278.4 | K43: 369.2
C44: Total DUV Revenue | G44: =SUM(G40:G43) -> 5502.7 | H44: =SUM(H40:H43) -> 6855.1 | I44: =SUM(I40:I43) -> 7725.4 | J44: =SUM(J40:J43) -> 12278.5 | K44: =SUM(K40:K43) -> 12801.8 | L44: =L19*L31 -> 12800 | M44: =M19*M31 -> 13940 | N44: =N19*N31 -> 15120 | O44: =O19*O31 -> 15910 | P44: =P19*P31 -> 16720
C46: Metrology Revenue | G46: 350.1 | H46: 513.7 | I46: 659.6 | J46: 536.1 | K46: 645.5 | L46: =K46*(1+Assumptions!M48) -> 735.87 | M46: =L46*(1+Assumptions!N48) -> 824.1744 | N46: =M46*(1+Assumptions!O48) -> 914.83358 | O46: =N46*(1+Assumptions!P48) -> 997.16861 | P46: =O46*(1+Assumptions!Q48) -> 1086.9138
B48: Total Systems Revenue | G48: =G37+G38+G44+G46 -> 10316.6 | H48: =H37+H38+H44+H46 -> 13652.8 | I48: =I37+I38+I44+I46 -> 15430.3 | J48: =J37+J38+J44+J46 -> 21938.6 | K48: =K37+K38+K44+K46 -> 21768.7 | L48: =L37+L38+L44+L46 -> 24260.87 | M48: =M37+M38+M44+M46 -> 28089.174 | N48: =N37+N38+N44+N46 -> 32159.834 | ... P48: =P37+P38+P44+P46 -> 38206.914
B51: SERVICES
C52: Service Revenue % of Systems | G52: =G53/G48 -> 0.35495221 | H52: =H53/H48 -> 0.3631636 | I52: =I53/I48 -> 0.37219626 | J52: =J53/J48 -> 0.25616493 | K52: =K53/K48 -> 0.29832742 | L52: =Assumptions!M50 -> 0.305 | M52: =Assumptions!N50 -> 0.31 | N52: =Assumptions!O50 -> 0.315 | O52: =Assumptions!P50 -> 0.32 | P52: =Assumptions!Q50 -> 0.325
C53: Service Revenue | G53: 3661.9 | H53: 4958.2 | I53: 5743.1 | J53: 5619.9 | K53: 6494.2 | L53: =L52*L48 -> 7399.5653 | M53: =M52*M48 -> 8707.6441 | N53: =N52*N48 -> 10130.348 | O53: =O52*O48 -> 11298.294 | P53: =P52*P48 -> 12417.247
B55: Total Revenue | F55: ($ MM) | G55: =G48+G53 -> 13978.5 | H55: =H48+H53 -> 18611 | I55: =I48+I53 -> 21173.4 | J55: =J48+J53 -> 27558.5 | K55: =K48+K53 -> 28262.9 | L55: =L48+L53 -> 31660.435 | M55: =M48+M53 -> 36796.818 | N55: =N48+N53 -> 42290.181 | ... P55: =P48+P53 -> 50624.161
P60: =$P$1 -> CURRENTLY RUNNING: BASE CASE SCENARIO
B61: =Assumptions!$C$2 -> ASML
B62: Cost Schedule
...

Sheet Valuation
B2: =Assumptions!C2 -> ASML
B3: WACC Schedule
B5: (€ Millions)
B7: Cost of Equity
C8: Risk-free Rate | G8: =Assumptions!Q23 -> 0.0299
C9: Equity Risk Premium | G9: =Assumptions!Q25 -> 0.055
C10: Beta (levered) | G10: =Assumptions!Q24 -> 1.46
C11: Cost Of Equity | G11: =G8+G10*G9 -> 0.1102
B13: Cost of Debt
C14: Pre-Tax Cost of Debt | G14: =Assumptions!Q13 -> 0.035
C15: Tax Rate | G15: =Assumptions!Q18 -> 0.16
C16: After-Tax Cost of Debt | G16: =G14*(1-G15) -> 0.0294
B18: Capital Structure
C19: Market Cap | G19: =Assumptions!Q28*Assumptions!Q29 -> 454617.84
C20: Total Debt | G20: =Model!K366+Model!K373 -> 3677.3
C21: Total Capital | G21: =G19+G20 -> 458295.14
C22: Equity Weight | G22: =G19/G21 -> 0.99197613
C23: Debt Weight | G23: =1-G22 -> 0.0080238686
C25: WACC | G25: =G22*G11+G23*G16 -> 0.10955167
B31: =B2 -> ASML
B32: Free Cash Flow to Firm (FCFF) Schedule
B34: (€ Millions)
L35: Projected
G36: =H36-1 -> 2020 | H36: =I36-1 -> 2021 | I36: =J36-1 -> 2022 | J36: =K36-1 -> 2023 | K36: =L36-1 -> 2024 | L36: =Assumptions!H11 -> 2025 | M36: =L36+1 -> 2026 | N36: =M36+1 -> 2027 | O36: =N36+1 -> 2028 | P36: =O36+1 -> 2029
C38: EBIT | L38: =Model!L272 -> 10985.443 | M38: =Model!M272 -> 12761.193 | N38: =Model!N272 -> 14658.935 | O38: =Model!O272 -> 16146.674 | P38: =Model!P272 -> 17530.287
C39: Tax Rate | L39: =Assumptions!Q18 -> 0.16 | M39: =L39 -> 0.16 | N39: =M39 -> 0.16 | O39: =N39 -> 0.16 | P39: =O39 -> 0.16
C40: NOPAT | L40: =L38*(1-L39) -> 9227.7723 | M40: =M38*(1-M39) -> 10719.402 | N40: =N38*(1-N39) -> 12313.505 | O40: =O38*(1-O39) -> 13563.206 | P40: =P38*(1-P39) -> 14725.441
C42: Depreciation & Amortization | L42: =Model!L305 -> 1849.158 | M42: =Model!M305 -> 2040.174 | N42: =Model!N305 -> 2436.483 | O42: =Model!O305 -> 3076.055 | P42: =Model!P305 -> 3578.9109
C43: Changes in Working Capital | L43: =-Model!L308 -> -649.87371 | M43: =-Model!M308 -> -603.70454 | N43: =-Model!N308 -> -357.01936 | O43: =-Model!O308 -> -628.61121 | P43: =-Model!P308 -> -337.8583
C44: CapEx | L44: =Model!L314 -> -1899.6261 | M44: =Model!M314 -> -2207.8091 | N44: =Model!N314 -> -2537.4109 | O44: =Model!O314 -> -2796.3278 | P44: =Model!P314 -> -3037.4496
C45: Capitalized Development Costs | L45: =Model!L315 -> -1266.4174 | M45: =Model!M315 -> -1471.8727 | N45: =Model!N315 -> -1691.6072 | O45: =Model!O315 -> -1864.2185 | P45: =Model!P315 -> -2024.9664
C46: Change in Total Finance Receivables | L46: =Model!L316 -> -1375.1 | M46: =Model!M316 -> 0 | N46: =Model!N316 -> 0 | O46: =Model!O316 -> 0 | P46: =Model!P316 -> 0
C47: FCFF | L47: =SUM(L40:L46) -> 5885.9131 | M47: =SUM(M40:M46) -> 8476.1896 | N47: =SUM(N40:N46) -> 10163.951 | O47: =SUM(O40:O46) -> 11350.104 | P47: =SUM(P40:P46) -> 12904.078
C48: YoY Growth | M48: =M47/L47-1 -> 0.44008065 | N48: =N47/M47-1 -> 0.19911788 | O48: =O47/N47-1 -> 0.11670201 | P48: =P47/O47-1 -> 0.13691274
B55: =B2 -> ASML
B56: DCF & Terminal Value Schedule
B58: (€ Millions)
L59: Projected
G60: =H60-1 -> 2020 | H60: =I60-1 -> 2021 | I60: =J60-1 -> 2022 | J60: =K60-1 -> 2023 | K60: =L60-1 -> 2024 | L60: =L36 -> 2025 | M60: =L60+1 -> 2026 | N60: =M60+1 -> 2027 | O60: =N60+1 -> 2028 | P60: =O60+1 -> 2029
C62: FCFF | L62: =L47 -> 5885.9131 | M62: =M47 -> 8476.1896 | N62: =N47 -> 10163.951 | O62: =O47 -> 11350.104 | P62: =P47 -> 12904.078
...
